Workbook

Sheet Resumo
A1: Condicionantes ambientais – pendências
A2: Fonte: licenças e documentos das pastas dos clientes (RN Projetos). Itens marcados como "já atendidos" (placa, publicação, treinamento, INMETRO e laudo) não aparecem, exceto licenças emitidas em 2026.
A3: Data de referência | B3: 46318 | C3: ← altere para atualizar os dias de atraso na aba Pendências
A5: Condicionante | B5: Vencidas | C5: Sem data | D5: Vencem em breve | E5: Total
A6: Renovação da licença | B6: =COUNTIFS(Pendências!$H$2:$H$135,$A6,Pendências!$J$2:$J$135,"Vencida") -> 12 | C6: =COUNTIFS(Pendências!$H$2:$H$135,$A6,Pendências!$J$2:$J$135,"Sem data") -> 0 | D6: =COUNTIFS(Pendências!$H$2:$H$135,$A6,Pendências!$J$2:$J$135,"Vence em breve") -> 0 | E6: =SUM(B6:D6) -> 12
A7: IBAMA – Certificado de Regularidade | B7: =COUNTIFS(Pendências!$H$2:$H$135,$A7,Pendências!$J$2:$J$135,"Vencida") -> 7 | C7: =COUNTIFS(Pendências!$H$2:$H$135,$A7,Pendências!$J$2:$J$135,"Sem data") -> 0 | D7: =COUNTIFS(Pendências!$H$2:$H$135,$A7,Pendências!$J$2:$J$135,"Vence em breve") -> 4 | E7: =SUM(B7:D7) -> 11
A8: IBAMA – TCFA em aberto | B8: =COUNTIFS(Pendências!$H$2:$H$135,$A8,Pendências!$J$2:$J$135,"Vencida") -> 1 | C8: =COUNTIFS(Pendências!$H$2:$H$135,$A8,Pendências!$J$2:$J$135,"Sem data") -> 0 | D8: =COUNTIFS(Pendências!$H$2:$H$135,$A8,Pendências!$J$2:$J$135,"Vence em breve") -> 0 | E8: =SUM(B8:D8) -> 1
A9: Publicação da concessão | B9: =COUNTIFS(Pendências!$H$2:$H$135,$A9,Pendências!$J$2:$J$135,"Vencida") -> 6 | C9: =COUNTIFS(Pendências!$H$2:$H$135,$A9,Pendências!$J$2:$J$135,"Sem data") -> 0 | D9: =COUNTIFS(Pendências!$H$2:$H$135,$A9,Pendências!$J$2:$J$135,"Vence em breve") -> 0 | E9: =SUM(B9:D9) -> 6
A10: Placa indicativa | B10: =COUNTIFS(Pendências!$H$2:$H$135,$A10,Pendências!$J$2:$J$135,"Vencida") -> 4 | C10: =COUNTIFS(Pendências!$H$2:$H$135,$A10,Pendências!$J$2:$J$135,"Sem data") -> 0 | D10: =COUNTIFS(Pendências!$H$2:$H$135,$A10,Pendências!$J$2:$J$135,"Vence em breve") -> 1 | E10: =SUM(B10:D10) -> 5
A11: ANP – Certificado de posto revendedor | B11: =COUNTIFS(Pendências!$H$2:$H$135,$A11,Pendências!$J$2:$J$135,"Vencida") -> 1 | C11: =COUNTIFS(Pendências!$H$2:$H$135,$A11,Pendências!$J$2:$J$135,"Sem data") -> 1 | D11: =COUNTIFS(Pendências!$H$2:$H$135,$A11,Pendências!$J$2:$J$135,"Vence em breve") -> 0 | E11: =SUM(B11:D11) -> 2
A12: AVCB / CLCB (Bombeiros) | B12: =COUNTIFS(Pendências!$H$2:$H$135,$A12,Pendências!$J$2:$J$135,"Vencida") -> 23 | C12: =COUNTIFS(Pendências!$H$2:$H$135,$A12,Pendências!$J$2:$J$135,"Sem data") -> 8 | D12: =COUNTIFS(Pendências!$H$2:$H$135,$A12,Pendências!$J$2:$J$135,"Vence em breve") -> 3 | E12: =SUM(B12:D12) -> 34
A13: TOG – Óleos e graxas | B13: =COUNTIFS(Pendências!$H$2:$H$135,$A13,Pendências!$J$2:$J$135,"Vencida") -> 36 | C13: =COUNTIFS(Pendências!$H$2:$H$135,$A13,Pendências!$J$2:$J$135,"Sem data") -> 8 | D13: =COUNTIFS(Pendências!$H$2:$H$135,$A13,Pendências!$J$2:$J$135,"Vence em breve") -> 0 | E13: =SUM(B13:D13) -> 44
A14: INMETRO – Bombas | B14: =COUNTIFS(Pendências!$H$2:$H$135,$A14,Pendências!$J$2:$J$135,"Vencida") -> 1 | C14: =COUNTIFS(Pendências!$H$2:$H$135,$A14,Pendências!$J$2:$J$135,"Sem data") -> 4 | D14: =COUNTIFS(Pendências!$H$2:$H$135,$A14,Pendências!$J$2:$J$135,"Vence em breve") -> 3 | E14: =SUM(B14:D14) -> 8
A15: Laudo de estanqueidade | B15: =COUNTIFS(Pendências!$H$2:$H$135,$A15,Pendências!$J$2:$J$135,"Vencida") -> 1 | C15: =COUNTIFS(Pendências!$H$2:$H$135,$A15,Pendências!$J$2:$J$135,"Sem data") -> 3 | D15: =COUNTIFS(Pendências!$H$2:$H$135,$A15,Pendências!$J$2:$J$135,"Vence em breve") -> 0 | E15: =SUM(B15:D15) -> 4
A16: Certificados de treinamento | B16: =COUNTIFS(Pendências!$H$2:$H$135,$A16,Pendências!$J$2:$J$135,"Vencida") -> 0 | C16: =COUNTIFS(Pendências!$H$2:$H$135,$A16,Pendências!$J$2:$J$135,"Sem data") -> 4 | D16: =COUNTIFS(Pendências!$H$2:$H$135,$A16,Pendências!$J$2:$J$135,"Vence em breve") -> 0 | E16: =SUM(B16:D16) -> 4
A17: Resíduos oleosos (relatório semestral) | B17: =COUNTIFS(Pendências!$H$2:$H$135,$A17,Pendências!$J$2:$J$135,"Vencida") -> 0 | C17: =COUNTIFS(Pendências!$H$2:$H$135,$A17,Pendências!$J$2:$J$135,"Sem data") -> 3 | D17: =COUNTIFS(Pendências!$H$2:$H$135,$A17,Pendências!$J$2:$J$135,"Vence em breve") -> 0 | E17: =SUM(B17:D17) -> 3
A18: TOTAL | B18: =SUM(B6:B17) -> 92 | C18: =SUM(C6:C17) -> 31 | D18: =SUM(D6:D17) -> 11 | E18: =SUM(E6:E17) -> 134
A20: Andamento (preenchido na aba Pendências)
A21: A fazer | B21: =COUNTIF(Pendências!$P$2:$P$135,A21) -> 134
A22: Em andamento | B22: =COUNTIF(Pendências!$P$2:$P$135,A22) -> 0
A23: Aguardando cliente | B23: =COUNTIF(Pendências!$P$2:$P$135,A23) -> 0
A24: Resolvido | B24: =COUNTIF(Pendências!$P$2:$P$135,A24) -> 0
A25: Já estava em dia | B25: =COUNTIF(Pendências!$P$2:$P$135,A25) -> 0
A27: Como usar: filtre a aba Pendências por Empresa, Condicionante ou Situação. Preencha Responsável, Andamento, Prazo combinado e Observações (colunas amarelas).

Sheet Pendências
A1: Nº | B1: Prioridade | C1: Empresa | D1: Município | E1: CNPJ | F1: Licença nº | G1: Validade da licença | H1: Condicionante | I1: Cond. nº na licença | J1: Situação | K1: Vencimento / último prazo | L1: Dias (+ falta / – atraso) | M1: De onde veio a data | N1: O que fazer | O1: Responsável | P1: Andamento | Q1: Prazo combinado | R1: Observações
A2: 1 | B2: Baixa | C2: Auto Posto Central Mineiro Ltda | D2: Frutuoso Gomes | E2: 34.086.384/0001-29 | F2: 2020-156385/TEC/LO-0056 | G2: 46505 | H2: IBAMA – Certificado de Regularidade | J2: Vence em breve | K2: 46344 | L2: =IF(K2="","",K2-Resumo!$B$3) -> 26 | M2: Documento na pasta: Certificado de Regularidade (CTF/APP) emitido em 18/08/2026 | N2: Emitir novo Certificado de Regularidade (CTF/APP) no site do IBAMA (vale 3 meses) e arquivar na pasta. | P2: A fazer
A3: 2 | B3: Baixa | C3: Auto Posto Central Mineiro Ltda | D3: Frutuoso Gomes | E3: 34.086.384/0001-29 | F3: 2020-156385/TEC/LO-0056 | G3: 46505 | H3: AVCB / CLCB (Bombeiros) | I3: 4 | J3: Vence em breve | K3: 46344 | L3: =IF(K3="","",K3-Resumo!$B$3) -> 26 | M3: Documento na pasta: AVCB nº 65529 emitido em 18/11/2025 | N3: Conferir com o cliente se há AVCB/CLCB mais recente ou renovação em andamento; se não, solicitar renovação ao Corpo de Bombeiros e protocolar o novo no Comunic@. | P3: A fazer
A4: 3 | B4: Alta | C4: Auto Posto Central Mineiro Ltda | D4: Frutuoso Gomes | E4: 34.086.384/0001-29 | F4: 2020-156385/TEC/LO-0056 | G4: 46505 | H4: TOG – Óleos e graxas | I4: 13 | J4: Vencida | K4: 46281 | L4: =IF(K4="","",K4-Resumo!$B$3) -> -37 | M4: Documento na pasta: Coleta em 16/06/2026 → +3 meses | N4: Programar nova coleta de óleos e graxas (a cada 3 meses) e protocolar o laudo no Comunic@. Conferir se já existe laudo mais recente. | P4: A fazer
A5: 4 | B5: Alta | C5: Auto Posto Lopes Combustiveis Ltda | D5: Viçosa | E5: 22.497.882/0001-85 | F5: 2023-194569/TEC/RLO-0313 | G5: 47374 | H5: AVCB / CLCB (Bombeiros) | I5: 5 | J5: Vencida | K5: 45995 | L5: =IF(K5="","",K5-Resumo!$B$3) -> -323 | M5: Documento na pasta: AVCB emitido em 04/12/2024 | N5: Conferir com o cliente se há AVCB/CLCB mais recente ou renovação em andamento; se não, solicitar renovação ao Corpo de Bombeiros e protocolar o novo no Comunic@. | P5: A fazer
A6: 5 | B6: Alta | C6: Auto Posto Lopes Combustiveis Ltda | D6: Viçosa | E6: 22.497.882/0001-85 | F6: 2023-194569/TEC/RLO-0313 | G6: 47374 | H6: TOG – Óleos e graxas | I6: 16 | J6: Vencida | K6: 46281 | L6: =IF(K6="","",K6-Resumo!$B$3) -> -37 | M6: Documento na pasta: Coleta em 16/06/2026 → +3 meses | N6: Programar nova coleta de óleos e graxas (a cada 3 meses) e protocolar o laudo no Comunic@. Conferir se já existe laudo mais recente. | P6: A fazer
A7: 6 | B7: Alta | C7: Auto Posto Maioridade Ltda | D7: Martins | E7: 23.475.547/0001-49 | F7: 2023-201498/TEC/RLO-0710 | G7: 47584 | H7: AVCB / CLCB (Bombeiros) | I7: 5 | J7: Vencida | K7: 46309 | L7: =IF(K7="","",K7-Resumo!$B$3) -> -9 | M7: Documento na pasta: AVCB nº 65330 emitido em 14/10/2025 | N7: Conferir com o cliente se há AVCB/CLCB mais recente ou renovação em andamento; se não, solicitar renovação ao Corpo de Bombeiros e protocolar o novo no Comunic@. | P7: A fazer
A8: 7 | B8: Alta | C8: Auto Posto Maioridade Ltda | D8: Martins | E8: 23.475.547/0001-49 | F8: 2023-201498/TEC/RLO-0710 | G8: 47584 | H8: TOG – Óleos e graxas | I8: 17 | J8: Vencida | K8: 46281 | L8: =IF(K8="","",K8-Resumo!$B$3) -> -37 | M8: Documento na pasta: Coleta em 16/06/2026 → +3 meses | N8: Programar nova coleta de óleos e graxas (a cada 3 meses) e protocolar o laudo no Comunic@. Conferir se já existe laudo mais recente. | P8: A fazer
A9: 8 | B9: Baixa | C9: Auto Posto Santo Expedito Eireli | D9: Tenente Ananias | E9: 03.445.752/0001-54 | F9: 2020-157554/TEC/LO-0286 | G9: 46546 | H9: TOG – Óleos e graxas | I9: 14 | J9: Sem data | L9: =IF(K9="","",K9-Resumo!$B$3) | M9: Informe a data do último envio | N9: Programar nova coleta de óleos e graxas (a cada 3 meses) e protocolar o laudo no Comunic@. Conferir se já existe laudo mais recente. | P9: A fazer
A10: 9 | B10: Média | C10: Auto Posto Taboleiro Ltda | D10: Taboleiro Grande | E10: 51.502.654/0001-54 | F10: 2021-159236/TEC/RLO-0032 | G10: 46764 | H10: Publicação da concessão | I10: 21 | J10: Vencida | K10: 46101 | L10: =IF(K10="","",K10-Resumo!$B$3) -> -217 | M10: Prazo único de 10 dias após a emissão | N10: Conferir se a concessão foi publicada (D.O.E. e jornal) e protocolar a cópia no Comunic@. | P10: A fazer
A11: 10 | B11: Média | C11: Auto Posto Taboleiro Ltda | D11: Taboleiro Grande | E11: 51.502.654/0001-54 | F11: 2021-159236/TEC/RLO-0032 | G11: 46764 | H11: Placa indicativa | I11: 19 | J11: Vencida | K11: 46181 | L11: =IF(K11="","",K11-Resumo!$B$3) -> -137 | M11: Prazo único de 90 dias após a emissão | N11: Conferir foto da placa indicativa (modelo IDEMA) e protocolar no Comunic@. | P11: A fazer
A12: 11 | B12: Alta | C12: Auto Posto Taboleiro Ltda | D12: Taboleiro Grande | E12: 51.502.654/0001-54 | F12: 2021-159236/TEC/RLO-0032 | G12: 46764 | H12: AVCB / CLCB (Bombeiros) | I12: 5 | J12: Vencida | K12: 46150 | L12: =IF(K12="","",K12-Resumo!$B$3) -> -168 | M12: Documento na pasta: AVCB emitido em 08/05/2025 | N12: Conferir com o cliente se há AVCB/CLCB mais recente ou renovação em andamento; se não, solicitar renovação ao Corpo de Bombeiros e protocolar o novo no Comunic@. | P12: A fazer
A13: 12 | B13: Alta | C13: Auto Posto Taboleiro Ltda | D13: Taboleiro Grande | E13: 51.502.654/0001-54 | F13: 2021-159236/TEC/RLO-0032 | G13: 46764 | H13: TOG – Óleos e graxas | I13: 16 | J13: Vencida | K13: 46282 | L13: =IF(K13="","",K13-Resumo!$B$3) -> -36 | M13: Documento na pasta: Coleta em 17/06/2026 → +3 meses | N13: Programar nova coleta de óleos e graxas (a cada 3 meses) e protocolar o laudo no Comunic@. Conferir se já existe laudo mais recente. | P13: A fazer
A14: 13 | B14: Baixa | C14: Auto Posto Taboleiro Ltda | D14: Taboleiro Grande | E14: 51.502.654/0001-54 | F14: 2021-159236/TEC/RLO-0032 | G14: 46764 | H14: INMETRO – Bombas | I14: 15 | J14: Sem data | L14: =IF(K14="","",K14-Resumo!$B$3) | M14: Informe a data do último envio | N14: Conferir verificação anual das bombas (IPEM/INMETRO); se vencida, solicitar vistoria e guardar os certificados. | P14: A fazer
A15: 14 | B15: Média | C15: Auto Posto Taboleiro Ltda | D15: Taboleiro Grande | E15: 51.502.654/0001-54 | F15: 2021-159236/TEC/RLO-0032 | G15: 46764 | H15: Laudo de estanqueidade | I15: 15 | J15: Vencida | K15: 46042 | L15: =IF(K15="","",K15-Resumo!$B$3) -> -276 | M15: Documento na pasta: Ensaio de 20/01/2021; 5 anos | N15: Conferir teste de estanqueidade (validade de 5 anos); se vencido ou inexistente, contratar novo laudo e protocolar. | P15: A fazer
A16: 15 | B16: Baixa | C16: Auto Posto Taboleiro Ltda | D16: Taboleiro Grande | E16: 51.502.654/0001-54 | F16: 2021-159236/TEC/RLO-0032 | G16: 46764 | H16: Certificados de treinamento | I16: 8 | J16: Sem data | L16: =IF(K16="","",K16-Resumo!$B$3) | M16: Informe a data do último envio | N16: Conferir certificados de treinamento (NR-20) dos funcionários e protocolar os atualizados. | P16: A fazer
A17: 16 | B17: Alta | C17: C.Dantas Teixeira Me | D17: Pau dos Ferros | E17: 10.325.617/0001-30 | F17: 2020-150229/TEC/RLO-0336 | G17: 46374 | H17: Renovação da licença | I17: 21 | J17: Vencida | K17: 46254 | L17: =IF(K17="","",K17-Resumo!$B$3) -> -64 | M17: Licença vale até 18/12/2026 (pedido ≥120 dias antes) | N17: Conferir se a renovação já foi requerida/emitida; se não, protocolar o pedido de renovação no IDEMA (mín. 120 dias antes do fim da validade). | P17: A fazer
A18: 17 | B18: Média | C18: C.Dantas Teixeira Me | D18: Pau dos Ferros | E18: 10.325.617/0001-30 | F18: 2020-150229/TEC/RLO-0336 | G18: 46374 | H18: IBAMA – Certificado de Regularidade | J18: Vencida | K18: 46303 | L18: =IF(K18="","",K18-Resumo!$B$3) -> -15 | M18: Documento na pasta: Certificado de Regularidade (CTF/APP) emitido em 08/07/2026 | N18: Emitir novo Certificado de Regularidade (CTF/APP) no site do IBAMA (vale 3 meses) e arquivar na pasta. | P18: A fazer
A19: 18 | B19: Baixa | C19: C.Dantas Teixeira Me | D19: Pau dos Ferros | E19: 10.325.617/0001-30 | F19: 2020-150229/TEC/RLO-0336 | G19: 46374 | H19: AVCB / CLCB (Bombeiros) | I19: 5 | J19: Sem data | L19: =IF(K19="","",K19-Resumo!$B$3) | M19: Informe a data do último envio | N19: Conferir com o cliente se há AVCB/CLCB mais recente ou renovação em andamento; se não, solicitar renovação ao Corpo de Bombeiros e protocolar o novo no Comunic@. | P19: A fazer
A20: 19 | B20: Baixa | C20: C.Dantas Teixeira Me | D20: Pau dos Ferros | E20: 10.325.617/0001-30 | F20: 2020-150229/TEC/RLO-0336 | G20: 46374 | H20: TOG – Óleos e graxas | I20: 17 | J20: Sem data | L20: =IF(K20="","",K20-Resumo!$B$3) | M20: Informe a data do último envio | N20: Programar nova coleta de óleos e graxas (a cada 3 meses) e protocolar o laudo no Comunic@. Conferir se já existe laudo mais recente. | P20: A fazer
A21: 20 | B21: Baixa | C21: Comercial De Petroleo M & M Santos Ltda | D21: Carnaubais | E21: 18.630.311/0001-08 | F21: 2025-246171/TEC/RLO-0573 | G21: 48100 | H21: TOG – Óleos e graxas | I21: 16 | J21: Sem data | L21: =IF(K21="","",K21-Resumo!$B$3) | M21: Informe a data do último envio | N21: Programar nova coleta de óleos e graxas (a cada 3 meses) e protocolar o laudo no Comunic@. Conferir se já existe laudo mais recente. | P21: A fazer
A22: 21 | B22: Alta | C22: Comercial Freitas Ltda - Posto Esperanca | D22: Almino Afonso | E22: 12.640.314/0001-38 | F22: 2008-023789/TEC/LRO-0174 | G22: 44080 | H22: Renovação da licença | I22: 24 | J22: Vencida | K22: 43960 | L22: =IF(K22="","",K22-Resumo!$B$3) -> -2358 | M22: Licença vale até 06/09/2020 (pedido ≥120 dias antes) | N22: Conferir se a renovação já foi requerida/emitida; se não, protocolar o pedido de renovação no IDEMA (mín. 120 dias antes do fim da validade). | P22: A fazer
A23: 22 | B23: Baixa | C23: Comercial Freitas Ltda - Posto Esperanca | D23: Almino Afonso | E23: 12.640.314/0001-38 | F23: 2008-023789/TEC/LRO-0174 | G23: 44080 | H23: IBAMA – Certificado de Regularidade | J23: Vence em breve | K23: 46346 | L23: =IF(K23="","",K23-Resumo!$B$3) -> 28 | M23: Documento na pasta: Certificado de Regularidade (CTF/APP) emitido em 20/08/2026 | N23: Emitir novo Certificado de Regularidade (CTF/APP) no site do IBAMA (vale 3 meses) e arquivar na pasta. | P23: A fazer
A24: 23 | B24: Baixa | C24: Comercial Freitas Ltda - Posto Esperanca | D24: Almino Afonso | E24: 12.640.314/0001-38 | F24: 2008-023789/TEC/LRO-0174 | G24: 44080 | H24: AVCB / CLCB (Bombeiros) | I24: 5 | J24: Sem data | L24: =IF(K24="","",K24-Resumo!$B$3) | M24: Informe a data do último envio | N24: Conferir com o cliente se há AVCB/CLCB mais recente ou renovação em andamento; se não, solicitar renovação ao Corpo de Bombeiros e protocolar o novo no Comunic@. | P24: A fazer
A25: 24 | B25: Baixa | C25: Comercial Freitas Ltda - Posto Esperanca | D25: Almino Afonso | E25: 12.640.314/0001-38 | F25: 2008-023789/TEC/LRO-0174 | G25: 44080 | H25: TOG – Óleos e graxas | I25: 15 | J25: Sem data | L25: =IF(K25="","",K25-Resumo!$B$3) | M25: Informe a data do último envio | N25: Programar nova coleta de óleos e graxas (a cada 3 meses) e protocolar o laudo no Comunic@. Conferir se já existe laudo mais recente. | P25: A fazer
A26: 25 | B26: Baixa | C26: Comercial Rodrigues Dos Santos Ltda | D26: Assú | E26: 24.186.793/0001-43 | F26: 2021-160799/TEC/RLO-0226 | G26: 46595 | H26: AVCB / CLCB (Bombeiros) | I26: 5 | J26: Sem data | L26: =IF(K26="","",K26-Resumo!$B$3) | M26: Informe a data do último envio | N26: Conferir com o cliente se há AVCB/CLCB mais recente ou renovação em andamento; se não, solicitar renovação ao Corpo de Bombeiros e protocolar o novo no Comunic@. | P26: A fazer
A27: 26 | B27: Baixa | C27: Comercial Rodrigues Dos Santos Ltda | D27: Assú | E27: 24.186.793/0001-43 | F27: 2021-160799/TEC/RLO-0226 | G27: 46595 | H27: TOG – Óleos e graxas | I27: 15 | J27: Sem data | L27: =IF(K27="","",K27-Resumo!$B$3) | M27: Informe a data do último envio | N27: Programar nova coleta de óleos e graxas (a cada 3 meses) e protocolar o laudo no Comunic@. Conferir se já existe laudo mais recente. | P27: A fazer
A28: 27 | B28: Média | C28: Comercio De Combustiveis Santo Antonio Ltda | D28: Severiano Melo | E28: 58.058.585/0001-80 | F28: 2025-248521/TEC/LO-0297 | G28: 48215 | H28: Publicação da concessão | I28: 19 | J28: Vencida | K28: 46034 | L28: =IF(K28="","",K28-Resumo!$B$3) -> -284 | M28: Prazo único de 10 dias após a emissão | N28: Conferir se a concessão foi publicada (D.O.E. e jornal) e protocolar a cópia no Comunic@. | P28: A fazer
A29: 28 | B29: Média | C29: Comercio De Combustiveis Santo Antonio Ltda | D29: Severiano Melo | E29: 58.058.585/0001-80 | F29: 2025-248521/TEC/LO-0297 | G29: 48215 | H29: Placa indicativa | I29: 17 | J29: Vencida | K29: 46114 | L29: =IF(K29="","",K29-Resumo!$B$3) -> -204 | M29: Prazo único de 90 dias após a emissão | N29: Conferir foto da placa indicativa (modelo IDEMA) e protocolar no Comunic@. | P29: A fazer
A30: 29 | B30: Alta | C30: Comercio De Combustiveis Santo Antonio Ltda | D30: Severiano Melo | E30: 58.058.585/0001-80 | F30: 2025-248521/TEC/LO-0297 | G30: 48215 | H30: TOG – Óleos e graxas | I30: 15 | J30: Vencida | K30: 46281 | L30: =IF(K30="","",K30-Resumo!$B$3) -> -37 | M30: Documento na pasta: Coleta em 16/06/2026 → +3 meses | N30: Programar nova coleta de óleos e graxas (a cada 3 meses) e protocolar o laudo no Comunic@. Conferir se já existe laudo mais recente. | P30: A fazer
A31: 30 | B31: Baixa | C31: Comercio De Combustiveis Santo Antonio Ltda | D31: Severiano Melo | E31: 58.058.585/0001-80 | F31: 2025-248521/TEC/LO-0297 | G31: 48215 | H31: INMETRO – Bombas | I31: 8 | J31: Sem data | L31: =IF(K31="","",K31-Resumo!$B$3) | M31: Informe a data do último envio | N31: Conferir verificação anual das bombas (IPEM/INMETRO); se vencida, solicitar vistoria e guardar os certificados. | P31: A fazer
A32: 31 | B32: Baixa | C32: Comercio De Combustiveis Santo Antonio Ltda | D32: Severiano Melo | E32: 58.058.585/0001-80 | F32: 2025-248521/TEC/LO-0297 | G32: 48215 | H32: Laudo de estanqueidade | I32: 14 | J32: Sem data | L32: =IF(K32="","",K32-Resumo!$B$3) | M32: Informe a data do último envio | N32: Conferir teste de estanqueidade (validade de 5 anos); se vencido ou inexistente, contratar novo laudo e protocolar. | P32: A fazer
A33: 32 | B33: Baixa | C33: Comercio De Combustiveis Santo Antonio Ltda | D33: Severiano Melo | E33: 58.058.585/0001-80 | F33: 2025-248521/TEC/LO-0297 | G33: 48215 | H33: Certificados de treinamento | I33: 8 | J33: Sem data | L33: =IF(K33="","",K33-Resumo!$B$3) | M33: Informe a data do último envio | N33: Conferir certificados de treinamento (NR-20) dos funcionários e protocolar os atualizados. | P33: A fazer
A34: 33 | B34: Alta | C34: Coronel Gas Ii Ltda | D34: Município São Miguel | E34: 56.086.886/0001-92 | F34: 2024-219372/TEC/LO-0637 | G34: 47766 | H34: AVCB / CLCB (Bombeiros) | I34: 4 | J34: Vencida | K34: 45995 | L34: =IF(K34="","",K34-Resumo!$B$3) -> -323 | M34: Documento na pasta: AVCB emitido em 04/12/2024 | N34: Conferir com o cliente se há AVCB/CLCB mais recente ou renovação em andamento; se não, solicitar renovação ao Corpo de Bombeiros e protocolar o novo no Comunic@. | P34: A fazer
A35: 34 | B35: Alta | C35: Damiana Maria De Jesus Dantas Varejista | D35: Venha Ver | E35: 10.973.484/0001-09 | F35: 2022-180904/TEC/RLO-0170 | G35: 47037 | H35: AVCB / CLCB (Bombeiros) | I35: 5 | J35: Vencida | K35: 46225 | L35: =IF(K35="","",K35-Resumo!$B$3) -> -93 | M35: Documento na pasta: AVCB emitido em 22/07/2025 | N35: Conferir com o cliente se há AVCB/CLCB mais recente ou renovação em andamento; se não, solicitar renovação ao Corpo de Bombeiros e protocolar o novo no Comunic@. | P35: A fazer
A36: 35 | B36: Alta | C36: Damiana Maria De Jesus Dantas Varejista | D36: Venha Ver | E36: 10.973.484/0001-09 | F36: 2022-180904/TEC/RLO-0170 | G36: 47037 | H36: TOG – Óleos e graxas | I36: 15 | J36: Vencida | K36: 46282 | L36: =IF(K36="","",K36-Resumo!$B$3) -> -36 | M36: Documento na pasta: Coleta em 17/06/2026 → +3 meses | N36: Programar nova coleta de óleos e graxas (a cada 3 meses) e protocolar o laudo no Comunic@. Conferir se já existe laudo mais recente. | P36: A fazer
A37: 36 | B37: Média | C37: Estevam E Castro Posto De Combustivel Ltda | D37: Encanto | E37: 06.287.722/0001-55 | F37: 2025-250825/TEC/RLO-0982 | G37: 48208 | H37: IBAMA – TCFA em aberto | J37: Vencida | K37: 45322 | L37: =IF(K37="","",K37-Resumo!$B$3) -> -996 | M37: Documento na pasta: 6 boletos TCFA em aberto na pasta: 2022/3 a 2023/4, todos com vencimento em 31/01/2024 | N37: Conferir o pagamento dos boletos TCFA em aberto (2022/3 a 2023/4); se não pagos, emitir 2ª via ou parcelamento no IBAMA. | P37: A fazer
A38: 37 | B38: Alta | C38: Estevam E Castro Posto De Combustivel Ltda | D38: Encanto | E38: 06.287.722/0001-55 | F38: 2025-250825/TEC/RLO-0982 | G38: 48208 | H38: AVCB / CLCB (Bombeiros) | I38: 5 | J38: Vencida | K38: 46239 | L38: =IF(K38="","",K38-Resumo!$B$3) -> -79 | M38: Documento na pasta: AVCB emitido em 05/08/2025 | N38: Conferir com o cliente se há AVCB/CLCB mais recente ou renovação em andamento; se não, solicitar renovação ao Corpo de Bombeiros e protocolar o novo no Comunic@. | P38: A fazer
A39: 38 | B39: Alta | C39: Estevam E Castro Posto De Combustivel Ltda | D39: Encanto | E39: 06.287.722/0001-55 | F39: 2025-250825/TEC/RLO-0982 | G39: 48208 | H39: TOG – Óleos e graxas | I39: 10 | J39: Vencida | K39: 46282 | L39: =IF(K39="","",K39-Resumo!$B$3) -> -36 | M39: Documento na pasta: Coleta em 17/06/2026 → +3 meses | N39: Programar nova coleta de óleos e graxas (a cada 3 meses) e protocolar o laudo no Comunic@. Conferir se já existe laudo mais recente. | P39: A fazer
A40: 39 | B40: Baixa | C40: Estevam E Castro Posto De Combustivel Ltda | D40: Encanto | E40: 06.287.722/0001-55 | F40: 2025-250825/TEC/RLO-0982 | G40: 48208 | H40: Resíduos oleosos (relatório semestral) | I40: 11 | J40: Sem data | L40: =IF(K40="","",K40-Resumo!$B$3) | M40: Informe a data do último envio | N40: Reunir comprovantes de coleta/destinação de resíduos oleosos e protocolar semestralmente. | P40: A fazer
...

Sheet Por empresa
A1: Empresa | B1: Vencidas | C1: Sem data | D1: Vencem em breve | E1: Total | F1: Prioridade alta
A2: Auto Posto Central Mineiro Ltda | B2: =COUNTIFS(Pendências!$C$2:$C$135,$A2,Pendências!$J$2:$J$135,"Vencida") -> 1 | C2: =COUNTIFS(Pendências!$C$2:$C$135,$A2,Pendências!$J$2:$J$135,"Sem data") -> 0 | D2: =COUNTIFS(Pendências!$C$2:$C$135,$A2,Pendências!$J$2:$J$135,"Vence em breve") -> 2 | E2: =SUM(B2:D2) -> 3 | F2: =COUNTIFS(Pendências!$C$2:$C$135,$A2,Pendências!$B$2:$B$135,"Alta") -> 1
A3: Auto Posto Lopes Combustiveis Ltda | B3: =COUNTIFS(Pendências!$C$2:$C$135,$A3,Pendências!$J$2:$J$135,"Vencida") -> 2 | C3: =COUNTIFS(Pendências!$C$2:$C$135,$A3,Pendências!$J$2:$J$135,"Sem data") -> 0 | D3: =COUNTIFS(Pendências!$C$2:$C$135,$A3,Pendências!$J$2:$J$135,"Vence em breve") -> 0 | E3: =SUM(B3:D3) -> 2 | F3: =COUNTIFS(Pendências!$C$2:$C$135,$A3,Pendências!$B$2:$B$135,"Alta") -> 2
A4: Auto Posto Maioridade Ltda | B4: =COUNTIFS(Pendências!$C$2:$C$135,$A4,Pendências!$J$2:$J$135,"Vencida") -> 2 | C4: =COUNTIFS(Pendências!$C$2:$C$135,$A4,Pendências!$J$2:$J$135,"Sem data") -> 0 | D4: =COUNTIFS(Pendências!$C$2:$C$135,$A4,Pendências!$J$2:$J$135,"Vence em breve") -> 0 | E4: =SUM(B4:D4) -> 2 | F4: =COUNTIFS(Pendências!$C$2:$C$135,$A4,Pendências!$B$2:$B$135,"Alta") -> 2
A5: Auto Posto Santo Expedito Eireli | B5: =COUNTIFS(Pendências!$C$2:$C$135,$A5,Pendências!$J$2:$J$135,"Vencida") -> 0 | C5: =COUNTIFS(Pendências!$C$2:$C$135,$A5,Pendências!$J$2:$J$135,"Sem data") -> 1 | D5: =COUNTIFS(Pendências!$C$2:$C$135,$A5,Pendências!$J$2:$J$135,"Vence em breve") -> 0 | E5: =SUM(B5:D5) -> 1 | F5: =COUNTIFS(Pendências!$C$2:$C$135,$A5,Pendências!$B$2:$B$135,"Alta") -> 0
A6: Auto Posto Taboleiro Ltda | B6: =COUNTIFS(Pendências!$C$2:$C$135,$A6,Pendências!$J$2:$J$135,"Vencida") -> 5 | C6: =COUNTIFS(Pendências!$C$2:$C$135,$A6,Pendências!$J$2:$J$135,"Sem data") -> 2 | D6: =COUNTIFS(Pendências!$C$2:$C$135,$A6,Pendências!$J$2:$J$135,"Vence em breve") -> 0 | E6: =SUM(B6:D6) -> 7 | F6: =COUNTIFS(Pendências!$C$2:$C$135,$A6,Pendências!$B$2:$B$135,"Alta") -> 2
A7: C.Dantas Teixeira Me | B7: =COUNTIFS(Pendências!$C$2:$C$135,$A7,Pendências!$J$2:$J$135,"Vencida") -> 2 | C7: =COUNTIFS(Pendências!$C$2:$C$135,$A7,Pendências!$J$2:$J$135,"Sem data") -> 2 | D7: =COUNTIFS(Pendências!$C$2:$C$135,$A7,Pendências!$J$2:$J$135,"Vence em breve") -> 0 | E7: =SUM(B7:D7) -> 4 | F7: =COUNTIFS(Pendências!$C$2:$C$135,$A7,Pendências!$B$2:$B$135,"Alta") -> 1
A8: Comercial De Petroleo M & M Santos Ltda | B8: =COUNTIFS(Pendências!$C$2:$C$135,$A8,Pendências!$J$2:$J$135,"Vencida") -> 0 | C8: =COUNTIFS(Pendências!$C$2:$C$135,$A8,Pendências!$J$2:$J$135,"Sem data") -> 1 | D8: =COUNTIFS(Pendências!$C$2:$C$135,$A8,Pendências!$J$2:$J$135,"Vence em breve") -> 0 | E8: =SUM(B8:D8) -> 1 | F8: =COUNTIFS(Pendências!$C$2:$C$135,$A8,Pendências!$B$2:$B$135,"Alta") -> 0
A9: Comercial Freitas Ltda - Posto Esperanca | B9: =COUNTIFS(Pendências!$C$2:$C$135,$A9,Pendências!$J$2:$J$135,"Vencida") -> 1 | C9: =COUNTIFS(Pendências!$C$2:$C$135,$A9,Pendências!$J$2:$J$135,"Sem data") -> 2 | D9: =COUNTIFS(Pendências!$C$2:$C$135,$A9,Pendências!$J$2:$J$135,"Vence em breve") -> 1 | E9: =SUM(B9:D9) -> 4 | F9: =COUNTIFS(Pendências!$C$2:$C$135,$A9,Pendências!$B$2:$B$135,"Alta") -> 1
A10: Comercial Rodrigues Dos Santos Ltda | B10: =COUNTIFS(Pendências!$C$2:$C$135,$A10,Pendências!$J$2:$J$135,"Vencida") -> 0 | C10: =COUNTIFS(Pendências!$C$2:$C$135,$A10,Pendências!$J$2:$J$135,"Sem data") -> 2 | D10: =COUNTIFS(Pendências!$C$2:$C$135,$A10,Pendências!$J$2:$J$135,"Vence em breve") -> 0 | E10: =SUM(B10:D10) -> 2 | F10: =COUNTIFS(Pendências!$C$2:$C$135,$A10,Pendências!$B$2:$B$135,"Alta") -> 0
A11: Comercio De Combustiveis Santo Antonio Ltda | B11: =COUNTIFS(Pendências!$C$2:$C$135,$A11,Pendências!$J$2:$J$135,"Vencida") -> 3 | C11: =COUNTIFS(Pendências!$C$2:$C$135,$A11,Pendências!$J$2:$J$135,"Sem data") -> 3 | D11: =COUNTIFS(Pendências!$C$2:$C$135,$A11,Pendências!$J$2:$J$135,"Vence em breve") -> 0 | E11: =SUM(B11:D11) -> 6 | F11: =COUNTIFS(Pendências!$C$2:$C$135,$A11,Pendências!$B$2:$B$135,"Alta") -> 1
A12: Coronel Gas Ii Ltda | B12: =COUNTIFS(Pendências!$C$2:$C$135,$A12,Pendências!$J$2:$J$135,"Vencida") -> 1 | C12: =COUNTIFS(Pendências!$C$2:$C$135,$A12,Pendências!$J$2:$J$135,"Sem data") -> 0 | D12: =COUNTIFS(Pendências!$C$2:$C$135,$A12,Pendências!$J$2:$J$135,"Vence em breve") -> 0 | E12: =SUM(B12:D12) -> 1 | F12: =COUNTIFS(Pendências!$C$2:$C$135,$A12,Pendências!$B$2:$B$135,"Alta") -> 1
A13: Damiana Maria De Jesus Dantas Varejista | B13: =COUNTIFS(Pendências!$C$2:$C$135,$A13,Pendências!$J$2:$J$135,"Vencida") -> 2 | C13: =COUNTIFS(Pendências!$C$2:$C$135,$A13,Pendências!$J$2:$J$135,"Sem data") -> 0 | D13: =COUNTIFS(Pendências!$C$2:$C$135,$A13,Pendências!$J$2:$J$135,"Vence em breve") -> 0 | E13: =SUM(B13:D13) -> 2 | F13: =COUNTIFS(Pendências!$C$2:$C$135,$A13,Pendências!$B$2:$B$135,"Alta") -> 2
... A46: Revendedora De Combustiveis R & R Eireli | B46: =COUNTIFS(Pendências!$C$2:$C$135,$A46,Pendências!$J$2:$J$135,"Vencida") -> 2 | C46: =COUNTIFS(Pendências!$C$2:$C$135,$A46,Pendências!$J$2:$J$135,"Sem data") -> 1 | D46: =COUNTIFS(Pendências!$C$2:$C$135,$A46,Pendências!$J$2:$J$135,"Vence em breve") -> 0 | E46: =SUM(B46:D46) -> 3 | F46: =COUNTIFS(Pendências!$C$2:$C$135,$A46,Pendências!$B$2:$B$135,"Alta") -> 2

Sheet Licenças que faltam
A1: Empresa | B1: CNPJ | C1: Situação | D1: Responsável | E1: Andamento
A2: Auto Posto Pais e Filhos | B2: 15.479.953/0001-51 | C2: Pasta 20 tem AVCB, ANP e TOG, mas não tem a licença do IDEMA
A3: Gás Coronel (Maria S N Gomes) | B3: 43.720.210/0001-67 | C3: Pasta 23 sem licença; AVCB é de revenda de GLP (confirmar se é gás)
A4: G J Santos de Oliveira – Areia Branca | B4: 70.156.112/0001-11 | C4: Pasta 29 tem ANP e TOG; falta a licença
A5: Posto Santa Rita I | B5: 07.766.121/0001-98 | C5: Pasta 32 tem ANP e AVCB; falta a licença
A6: A de Souza Leite Soares (Posto Anderson) | B6: 09.649.896/0001-09 | C6: Pasta 34 tem AVCB, ANP e INMETRO; falta a licença
A7: I C Soares Ltda JM | B7: 58.152.342/0001-07 | C7: Pasta 35 ainda não enviada
A8: Nosso Posto Lagoa Nova (Nosso Posto II) | B8: 17.439.147/0001-85 | C8: Pasta 15 ainda não enviada
A9: Ferreira & Galdêncio Petróleo | B9: — | C9: Pasta 42 tem AVCB e ANP; falta a licença
A10: C & A Ltda – Posto Independência | B10: 03.426.530/0001-94 | C10: Pasta não enviada; temos só 4 protocolos do Comunic@ (processo 2018-127422/TEC/RLO-1143)
A11: Posto Pinto – Severiano Melo | B11: 04.905.677/0001-20 | C11: Pasta 45 só tem ANP; falta a licença
A12: Distribuidora de Gás BG | B12: — | C12: Pasta 46 sem documentos
A13: Posto Saga | B13: 04.146.342/0001-75 | C13: Pasta 51 tem TOG e ANP; falta a licença
... A20: Pastas ainda não recebidas | B20: — | C20: Nº 2 (Posto da Serra), 9 e 15
